<?xml version="1.0" encoding="utf-8"?>
<!-- This URDF was automatically created by SolidWorks to URDF Exporter -->
<robot name="robot_arm_urdf">

  <!-- Base Link -->
  <link name="base_link">
    <inertial>
      <origin xyz="4.1633E-17 0 0.073876" rpy="0 0 0" />
      <mass value="17.147" />
      <inertia ixx="0.192" ixy="0" ixz="0" iyy="0.192" iyz="0" izz="0.29544" />
    </inertial>
    <visual>
      <origin xyz="0 0 0" rpy="0 0 0" />
      <geometry>
        <mesh filename="meshes/base_link.STL" />
      </geometry>
      <material name="">
        <color rgba="0.79216 0.81961 0.93333 1" />
      </material>
    </visual>
    <collision>
      <origin xyz="0 0 0" rpy="0 0 0" />
      <geometry>
        <mesh filename="meshes/base_link.STL" />
      </geometry>
    </collision>
  </link>

  <!-- Link 1 -->
  <link name="link_1">
    <inertial>
      <origin xyz="0 0.11047 0" rpy="0 0 0" />
      <mass value="3.0905" />
      <inertia ixx="0.026302" ixy="0" ixz="0" iyy="0.019632" iyz="0" izz="0.025388" />
    </inertial>
    <visual>
      <origin xyz="0 0 0" rpy="0 0 0" />
      <geometry>
        <mesh filename="meshes/link_1.STL" />
      </geometry>
      <material name="">
        <color rgba="1 1 1 1" />
      </material>
    </visual>
    <collision>
      <origin xyz="0 0 0" rpy="0 0 0" />
      <geometry>
        <mesh filename="meshes/link_1.STL" />
      </geometry>
    </collision>
  </link>

  <!-- Joint 1 -->
  <joint name="joint_1" type="revolute">
    <origin xyz="0 0 0.2" rpy="1.5708 0 1.5708" />
    <parent link="base_link" />
    <child link="link_1" />
    <axis xyz="0 1 0" />
    <limit lower="0" upper="3.142" effort="300" velocity="3" />
  </joint>

  <!-- Link 2 -->
  <link name="link_2">
    <inertial>
      <origin xyz="0 0.16752 0" rpy="0 0 0" />
      <mass value="5.5867" />
      <inertia ixx="0.12632" ixy="0" ixz="0" iyy="0.011401" iyz="0" izz="0.12911" />
    </inertial>
    <visual>
      <origin xyz="0 0 0" rpy="0 0 0" />
      <geometry>
        <mesh filename="meshes/link_2.STL" />
      </geometry>
      <material name="">
        <color rgba="0.79216 0.81961 0.93333 1" />
      </material>
    </visual>
    <collision>
      <origin xyz="0 0 0" rpy="0 0 0" />
      <geometry>
        <mesh filename="meshes/link_2.STL" />
      </geometry>
    </collision>
  </link>

  <!-- Joint 2 -->
  <joint name="joint_2" type="revolute">
    <origin xyz="0 0.205 0" rpy="0 0 0" />
    <parent link="link_1" />
    <child link="link_2" />
    <axis xyz="0 0 1" />
    <limit lower="-1.57" upper="1.57" effort="200" velocity="3" />
  </joint>

  <!-- Repeat the structure for remaining links and joints -->
  <!-- Link 3, Joint 3, Link 4, Joint 4, etc., follow the same structure -->

</robot>
