<?xml version="1.0" encoding="utf-8"?>
<robot name="robot_arm_urdf">
  <!-- Base Link -->
  <link name="base_link">
    <visual>
      <origin xyz="0 0 0" rpy="0 0 0" />
      <geometry>
        <mesh filename="C:/Users/MSI/python code/AR4_MK3/base_link.STL" />
      </geometry>
      <material name="gray">
        <color rgba="0.5 0.5 0.5 1.0" />
      </material>
    </visual>
    <collision>
      <origin xyz="0 0 0" rpy="0 0 0" />
      <geometry>
        <mesh filename="C:/Users/MSI/python code/AR4_MK3/base_link.STL" />
      </geometry>
    </collision>
    <inertial>
      <origin xyz="0 0 0" rpy="0 0 0" />
      <mass value="1.0" />
      <inertia 
        ixx="0.01" 
        ixy="0" 
        ixz="0" 
        iyy="0.01" 
        iyz="0" 
        izz="0.01" />
    </inertial>
  </link>

  <!-- Joint 1 -->
  <joint name="joint_1" type="revolute">
    <parent link="base_link"/>
    <child link="link_1"/>
    <origin xyz="0 0 0.0" rpy="3.14159 0 0"/>
    <axis xyz="0 0 1"/>
    <limit lower="-3.14" upper="3.14" effort="50" velocity="1.0"/>
  </joint>

  <!-- Link 1 -->
  <link name="link_1">
    <visual>
      <geometry>
        <mesh filename="C:/Users/MSI/python code/AR4_MK3/link_1.STL" />
      </geometry>
      <material name="blue">
        <color rgba="0 0 1 1"/>
      </material>
    </visual>
    <collision>
      <geometry>
        <mesh filename="C:/Users/MSI/python code/AR4_MK3/link_1.STL" />
      </geometry>
    </collision>
    <inertial>
      <origin xyz="0 0 0.25" rpy="0 0 0" />
      <mass value="2.0"/>
      <inertia 
        ixx="0.01" 
        ixy="0" 
        ixz="0" 
        iyy="0.01" 
        iyz="0" 
        izz="0.01" />
    </inertial>
  </link>


  <!-- Joint 2 -->
  <joint name="joint_2" type="revolute">
    <parent link="link_1"/>
    <child link="link_2"/>
    <!-- Position link_2 on top of link_1 -->
    <origin xyz="0 0.07 -0.17" rpy="1.57 0 -1.57"/>
    <axis xyz="0 1 0"/>
    <limit lower="-1.57" upper="1.57" effort="40" velocity="1.0"/>
  </joint>

  <!-- Link 2 -->
  <link name="link_2">
    <visual>
      <geometry>
        <mesh filename="C:/Users/MSI/python code/AR4_MK3/link_2.STL" />
      </geometry>
      <material name="green">
        <color rgba="0 1 0 1"/>
      </material>
    </visual>
    <collision>
      <geometry>
        <mesh filename="C:/Users/MSI/python code/AR4_MK3/link_2.STL" />
      </geometry>
    </collision>
    <inertial>
      <origin xyz="1.57  0.25" rpy="0 0 0" />
      <mass value="1.5"/>
      <inertia 
        ixx="0" 
        ixy="0" 
        ixz="0" 
        iyy="0" 
        iyz="0" 
        izz="0" />
    </inertial>
  </link> 
  
  <!-- Joint 3 -->
  <joint name="joint_3" type="continuous">
    <parent link="link_2"/>
    <child link="link_3"/>
    <origin xyz="-0.0125 -.30 0" rpy="0 0 -3.14"/>
    <axis xyz="1 0 0"/>
    <limit lower="-1.57" upper="1.57" effort="40" velocity="1.0"/>
  </joint>

  <!-- Link 3 -->
  <link name="link_3">
    <visual>
      <geometry>
        <mesh filename="C:/Users/MSI/python code/AR4_MK3/link_3.STL" />
      </geometry>
      <material name="red">
        <color rgba="1 0 0 1"/>
      </material>
    </visual>
    <collision>
      <geometry>
        <mesh filename="C:/Users/MSI/python code/AR4_MK3/link_3.STL" />
      </geometry>
    </collision>
    <inertial>
      <origin xyz="0 0 0.1" rpy="0 0 0" />
      <mass value="1.2"/>
      <inertia 
        ixx="0.005" 
        ixy="0" 
        ixz="0" 
        iyy="0.005" 
        iyz="0" 
        izz="0.005" />
    </inertial>
  </link> 

  <!-- Joint 4 -->
  <joint name="joint_4" type="continuous">
    <parent link="link_3"/>
    <child link="link_4"/>
    <origin xyz="0 0 0" rpy="0 -1.57 0"/>
    <axis xyz="1 0 0"/>
    <limit lower="-1.57" upper="1.57" effort="40" velocity="1.0"/>
  </joint>

  <!-- Link 4 -->
  <link name="link_4">
    <visual>
      <geometry>
        <mesh filename="C:/Users/MSI/python code/AR4_MK3/link_4.STL" />
      </geometry>
      <material name="yellow">
        <color rgba="0 1 1 1"/>
      </material>
    </visual>
    <collision>
      <geometry>
        <mesh filename="C:/Users/MSI/python code/AR4_MK3/link_4.STL" />
      </geometry>
    </collision>
    <inertial>
      <origin xyz="0 0 0.1" rpy="0 0 0" />
      <mass value="1.2"/>
      <inertia 
        ixx="0.005" 
        ixy="0" 
        ixz="0" 
        iyy="0.005" 
        iyz="0" 
        izz="0.005" />
    </inertial>
  </link>

  <!-- Joint 5  -->
  <joint name="joint_5" type="revolute">
    <parent link="link_4"/>
    <child link="link_5"/>
    <origin xyz="0 0 -.222" rpy="0 3.14 1.57"/>
    <axis xyz="1 0 0"/>
    <limit lower="-1.57" upper="1.57" effort="40" velocity="1.0"/>
  </joint>

  <!-- Link 5 -->
  <link name="link_5">
    <visual>
      <geometry>
        <mesh filename="C:/Users/MSI/python code/AR4_MK3/link_5.STL" />
      </geometry>
      <material name="white">
        <color rgba="1 0.4 1 1"/>
      </material>
    </visual>
    <collision>
      <geometry>
        <mesh filename="C:/Users/MSI/python code/AR4_MK3/link_5.STL" />
      </geometry>
    </collision>
    <inertial>
      <origin xyz="0 0 0.1" rpy="0 0 0" />
      <mass value="1.2"/>
      <inertia 
        ixx="0.004" 
        ixy="0" 
        ixz="0" 
        iyy="0.004" 
        iyz="0" 
        izz="0.004" />
    </inertial>
  </link>

  <!-- Joint 6  -->
  <joint name="joint_6" type="revolute">
    <parent link="link_5"/>
    <child link="link_6"/>
    <origin xyz="0 0 0.04" rpy="0 0 0"/>
    <axis xyz="1 0 0"/>
    <limit lower="-1.57" upper="1.57" effort="40" velocity="1.0"/>
  </joint>

  <!-- Link 6 -->
  <link name="link_6">
    <visual>
      <geometry>
        <mesh filename="C:/Users/MSI/python code/AR4_MK3/link_6.STL" />
      </geometry>
      <material name="white">
        <color rgba="0 1 0 1"/>
      </material>
    </visual>
    <collision>
      <geometry>
        <mesh filename="C:/Users/MSI/python code/AR4_MK3/link_6.STL" />
      </geometry>
    </collision>
    <inertial>
      <origin xyz="0 0 0.1" rpy="0 0 0" />
      <mass value="1.2"/>
      <inertia 
        ixx="0.005" 
        ixy="0" 
        ixz="0" 
        iyy="0.005" 
        iyz="0" 
        izz="0.005" />
    </inertial>
  </link>

  <!-- Gripper Joint -->
  <joint name="gripper_joint" type="fixed">
    <parent link="link_6"/>
    <child link="gripper_link"/>
    <origin xyz="0 0 0" rpy="-1.57 0 0"/> <!-- Adjust this position as required -->
  </joint>

  <!-- Gripper Link -->
  <link name="gripper_link">
    <visual>
      <geometry>
        <mesh filename="C:/Users/MSI/python code/AR4_MK3/gripper_base_link.STL" />
      </geometry>
      <material name="silver">
        <color rgba="0.1 0.1 0.8 1"/>
      </material>
    </visual>
    <collision>
      <geometry>
        <mesh filename="C:/Users/MSI/python code/AR4_MK3/gripper_base_link.STL" />
      </geometry>
    </collision>
    <inertial>
      <origin xyz="0 0 0" rpy="0 0 0" />
      <mass value="0.5"/>
      <inertia 
        ixx="0.001" 
        ixy="0" 
        ixz="0" 
        iyy="0.001" 
        iyz="0" 
        izz="0.001" />
    </inertial>
  </link>

   <!-- Gripper_jaw1 Joint -->
  <joint name="gripper_jaw1_joint" type="fixed">
    <parent link="gripper_link"/>
    <child link="gripper_jaw1_link"/>
    <origin xyz="-0.020 -0.04 0" rpy="3.14 3.14 -3.14"/> <!-- Adjust this position as required -->
  </joint>

  <!-- Gripper_jaw1 Link -->
  <link name="gripper_jaw1_link">
    <visual>
      <geometry>
        <mesh filename="C:/Users/MSI/python code/AR4_MK3/gripper_jaw1_link.STL" />
      </geometry>
      <material name="silver">
        <color rgba="1 1 1 1"/>
      </material>
    </visual>
    <collision>
      <geometry>
        <mesh filename="C:/Users/MSI/python code/AR4_MK3/gripper_jaw1_link.STL" />
      </geometry>
    </collision>
    <inertial>
      <origin xyz="0.24 0.2 .20" rpy="1.57 0 0" />
      <mass value="0.5"/>
      <inertia 
        ixx="0.001" 
        ixy="0" 
        ixz="0" 
        iyy="0.001" 
        iyz="0" 
        izz="0.001" />
    </inertial>
  </link>

   <!-- Gripper_jaw2 Joint -->
  <joint name="gripper_jaw2_joint" type="fixed">
    <parent link="gripper_link"/>
    <child link="gripper_jaw2_link"/>
    <origin xyz="0.020 -0.039 0" rpy="3.14 0 3.14"/> <!-- Adjust this position as required -->
  </joint>

  <!-- Gripper_jaw2 Link -->
  <link name="gripper_jaw2_link">
    <visual>
      <geometry>
        <mesh filename="C:/Users/MSI/python code/AR4_MK3/gripper_jaw2_link.STL" />
      </geometry>
      <material name="silver">
        <color rgba="1 1 1 1"/>
      </material>
    </visual>
    <collision>
      <geometry>
        <mesh filename="C:/Users/MSI/python code/AR4_MK3/gripper_jaw2_link.STL" />
      </geometry>
    </collision>
    <inertial>
      <origin xyz="0.24 0.2 .20" rpy="1.57 0 0" />
      <mass value="0.5"/>
      <inertia 
        ixx="0.001" 
        ixy="0" 
        ixz="0" 
        iyy="0.001" 
        iyz="0" 
        izz="0.001" />
    </inertial>
  </link>

  

  
</robot>
