<?xml version="1.0" encoding="utf-8"?>
<!-- Ye URDF ek robot arm ka base link define karta hai -->

<robot name="robot_arm_urdf">
  <!-- Robot ka naam hai "robot_arm_urdf" -->

  <!-- Base Link -->
  <link name="base_link">
    <!-- Ye robot ka base link hai, jo rigid body hai -->

    <!-- Inertial Properties (Dynamic properties define karta hai) -->
    <inertial>
      <!-- Origin define karta hai ki center of mass kaha hai -->
      <origin xyz="4.1633E-17 0 0.073876" rpy="0 0 0" />
      <!-- Link ka mass define karta hai -->
      <mass value="17.147" />
      <!-- Inertia tensor rotational inertia define karta hai -->
      <inertia ixx="0.192" ixy="0" ixz="0" iyy="0.192" iyz="0" izz="0.29544" />
    </inertial>

    <!-- Visual Properties (Display ke liye) -->
    <visual>
      <!-- Visual geometry ka position aur orientation -->
      <origin xyz="0 0 0" rpy="0 0 0" />
      <!-- Geometry ka shape ek external mesh file se define hota hai -->
      <geometry>
        <mesh filename="C:/Users/MSI/python code/base_link.STL" />
      </geometry>
      <!-- Material color set karta hai -->
      <material name="">
        <!-- RGBA color: light blue -->
        <color rgba="0.79216 0.81961 0.93333 1" />
      </material>
    </visual>

    <!-- Collision Properties (Physics engine ke liye) -->
    <collision>
      <!-- Collision geometry ka position aur orientation -->
      <origin xyz="0 0 0" rpy="0 0 0" />
      <!-- Geometry ka shape collision ke liye use hoga -->
      <geometry>
        <mesh filename="C:/Users/MSI/python code/base_link.STL" />
      </geometry>
    </collision>

  </link>

  <!-- Link 1 -->
  <link name="link_1">
    <inertial>
      <origin xyz="0 0.11047 0" rpy="0 0 0" />
      <mass value="3.0905" />
      <inertia ixx="0.026302" ixy="0" ixz="0" iyy="0.019632" iyz="0" izz="0.025388" />
    </inertial>
    <visual>
      <origin xyz="0 0 0" rpy="0 0 0" />
      <geometry>
        <mesh filename="C:/Users/MSI/python code/link_1.STL" />
      </geometry>
      <material name="">
        <color rgba="1 1 1 1" />
      </material>
    </visual>
    <collision>
      <origin xyz="0 0 0" rpy="0 0 0" />
      <geometry>
        <mesh filename="C:/Users/MSI/python code/link_1.STL" />
      </geometry>
    </collision>
  </link>

  <!-- Joint 1 -->
  <joint name="joint_1" type="revolute">
    <origin xyz="0 0 0.2" rpy="1.5708 0 1.5708" />
    <parent link="base_link" />
    <child link="link_1" />
    <axis xyz="0 1 0" />
    <limit lower="0" upper="3.142" effort="300" velocity="3" />
  </joint>

   <!-- Link 2 -->
  <link name="link_2">
    <inertial>
      <origin xyz="0 0.16752 0" rpy="0 0 0" />
      <mass value="5.5867" />
      <inertia ixx="0.12632" ixy="0" ixz="0" iyy="0.011401" iyz="0" izz="0.12911" />
    </inertial>
    <visual>
      <origin xyz="0 0 0" rpy="0 0 0" />
      <geometry>
       <mesh filename="C:/Users/MSI/python code/link_2.STL" />
      </geometry>
      <material name="">
        <color rgba="0.79216 0.81961 0.93333 1" />
      </material>
    </visual>
    <collision>
      <origin xyz="0 0 0" rpy="0 0 0" />
      <geometry>
        <mesh filename="C:/Users/MSI/python code/link_2.STL" />
      </geometry>
    </collision>
  </link>

  <!-- Joint 2 -->
  <joint name="joint_2" type="revolute">
    <origin xyz="0 0.205 0" rpy="0 0 0" />
    <parent link="link_1" />
    <child link="link_2" />
    <axis xyz="0 0 1" />
    <limit lower="-1.57" upper="1.57" effort="200" velocity="3" />
  </joint>

  <!-- Link 3 -->
  <link name="link_3">
    <!-- Inertial properties for link 3 -->
    <inertial>
      <origin xyz="-0.17893 0 0" rpy="0 0 0" />
      <mass value="2.8262" />
      <inertia ixx="0.0074041" ixy="0" ixz="0" iyy="0.028552" iyz="0" izz="0.025128" />
    </inertial>

    <!-- Visual properties for link 3 -->
    <visual>
      <origin xyz="0 0 0" rpy="0 0 0" />
      <geometry>
        <mesh filename="C:/Users/MSI/python code/link_3.STL" />
      </geometry>
      <material name="">
        <color rgba="0.79216 0.81961 0.93333 1" />
      </material>
    </visual>

    <!-- Collision properties for link 3 -->
    <collision>
      <origin xyz="0 0 0" rpy="0 0 0" />
      <geometry>
        <mesh filename="C:/Users/MSI/python code/link_3.STL" />
      </geometry>
    </collision>
  </link>

  <!-- Joint 3 -->
  <joint name="joint_3" type="revolute">
    <origin xyz="0 0.4 0" rpy="0 0 0" />
    <parent link="link_2" />
    <child link="link_3" />
    <axis xyz="0 0 1" />
    <limit lower="0" upper="3.142" effort="200" velocity="3" />
  </joint>

   <!-- Link 4 -->
  <link name="link_4">
    <!-- Inertial properties for link 4 -->
    <inertial>
      <origin xyz="-0.051672 0 0" rpy="0 0 0" />
      <mass value="1.8097" />
      <inertia ixx="0.0023112" ixy="0" ixz="0" iyy="0.0096102" iyz="0" izz="0.0093908" />
    </inertial>

    <!-- Visual properties for link 4 -->
    <visual>
      <origin xyz="0 0 0" rpy="0 0 0" />
      <geometry>
        <mesh filename="C:/Users/MSI/python code/link_4.STL" />
      </geometry>
      <material name="">
        <color rgba="0.79216 0.81961 0.93333 1" />
      </material>
    </visual>

    <!-- Collision properties for link 4 -->
    <collision>
      <origin xyz="0 0 0" rpy="0 0 0" />
      <geometry>
        <mesh filename="C:/Users/MSI/python code/link_4.STL" />
      </geometry>
    </collision>
  </link>

  <!-- Joint 4 -->
  <joint name="joint_4" type="revolute">
    <origin xyz="-0.35 0 0" rpy="0 0 1.5708" />
    <parent link="link_3" />
    <child link="link_4" />
    <axis xyz="0 0 1" />
    <limit lower="0" upper="-3.142" effort="200" velocity="3" />
  </joint>

  <!-- Link 5 -->
  <link name="link_5">
    <!-- Inertial properties for link 5 -->
    <inertial>
      <origin xyz="-0.018544 0 0" rpy="0 0 0" />
      <mass value="0.19053" />
      <inertia ixx="0.00030197" ixy="0" ixz="0" iyy="0.00022817" iyz="0" izz="0.00011843" />
    </inertial>

    <!-- Visual properties for link 5 -->
    <visual>
      <origin xyz="0 0 0" rpy="0 0 0" />
      <geometry>
        <mesh filename="C:/Users/MSI/python code/link_5.STL" />
      </geometry>
      <material name="">
        <color rgba="0.79216 0.81961 0.93333 1" />
      </material>
    </visual>

    <!-- Collision properties for link 5 -->
    <collision>
      <origin xyz="0 0 0" rpy="0 0 0" />
      <geometry>
        <mesh filename="C:/Users/MSI/python code/link_5.STL" />
      </geometry>
    </collision>
  </link>

  <!-- Joint 5 -->
  <joint name="joint_5" type="revolute">
    <origin xyz="-0.188 0 0" rpy="0 0 0" />
    <parent link="link_4" />
    <child link="link_5" />
    <axis xyz="1 0 0" />
    <limit lower="0" upper="3.142" effort="200" velocity="3" />
  </joint>

   <!-- Link 6 -->
  <link name="link_6">
    <!-- Inertial properties for link 6 -->
    <inertial>
      <origin xyz="-0.60237 0.4 -0.016013" rpy="0 0 0" />
      <mass value="0.11653" />
      <inertia ixx="3.9246E-05" ixy="0" ixz="0" iyy="7.1189E-05" iyz="0" izz="8.4875E-05" />
    </inertial>

    <!-- Visual properties for link 6 -->
    <visual>
      <origin xyz="0 0 0" rpy="0 0 0" />
      <geometry>
        <mesh filename="C:/Users/MSI/python code/link_6.STL" />
      </geometry>
      <material name="">
        <color rgba="0.79216 0.81961 0.93333 1" />
      </material>
    </visual>

    <!-- Collision properties for link 6 -->
    <collision>
      <origin xyz="0 0 0" rpy="0 0 0" />
      <geometry>
        <mesh filename="C:/Users/MSI/python code/link_6.STL" />
      </geometry>
    </collision>
  </link>

  <!-- Joint 6 -->
  <joint name="joint_6" type="prismatic">
    <origin xyz="0.54 -0.4 0" rpy="0 0 0" />
    <parent link="link_5" />
    <child link="link_6" />
    <axis xyz="0 0 -1" />
    <limit lower="0" upper="0.03" effort="100" velocity="3" />
  </joint>

    <!-- Link 7 -->
  <link name="link_7">
    <!-- Inertial Properties -->
    <inertial>
      <!-- Origin defines center of mass -->
      <origin xyz="-0.60237 0.4 -0.016013" rpy="0 0 0" />
      <!-- Mass of the link -->
      <mass value="0.11653" />
      <!-- Inertia Tensor -->
      <inertia
        ixx="3.9246E-05"
        ixy="-4.7946E-20"
        ixz="1.0258E-05"
        iyy="7.1189E-05"
        iyz="-3.946E-20"
        izz="8.4875E-05" />
    </inertial>

    <!-- Visual Properties -->
    <visual>
      <!-- Origin defines position and orientation of the visual -->
      <origin xyz="0 0 0" rpy="0 0 0" />
      <!-- Geometry of the visual -->
      <geometry>
        <mesh filename="C:/Users/MSI/python code/link_7.STL" />
      </geometry>
      <!-- Material color for visualization -->
      <material name="">
        <color rgba="0.79216 0.81961 0.93333 1" />
      </material>
    </visual>

    <!-- Collision Properties -->
    <collision>
      <!-- Origin defines position and orientation for collision -->
      <origin xyz="0 0 0" rpy="0 0 0" />
      <!-- Geometry of the collision detection -->
      <geometry>
        <mesh filename="C:/Users/MSI/python code/link_7.STL" />
      </geometry>
    </collision>
  </link>

  <!-- Joint 7 -->
  <joint name="joint_7" type="prismatic">
    <!-- Origin defines the joint's position and orientation -->
    <origin xyz="0.54 0.4 0" rpy="3.1416 0 0" />
    <!-- Parent link connected to the joint -->
    <parent link="link_5" />
    <!-- Child link connected to the joint -->
    <child link="link_7" />
    <!-- Motion direction (axis of translation) -->
    <axis xyz="0 0 1" />
    <!-- Joint motion limits -->
    <limit lower="-0.03" upper="0" effort="100" velocity="3" />
  </joint>


  

  <!-- Base link ka definition yahan khatam hota hai -->

</robot>
<!-- Robot ka definition close hota hai -->
